<?xml version="1.0" encoding="UTF-8"?>
<!-- Generated by org.testng.reporters.JUnitReportReporter -->
<testsuite hostname="vikash-PC" name="scripts.Demo" tests="2" failures="1" timestamp="9 Sep 2019 16:02:18 GMT" time="24.945" errors="1">
  <testcase name="createUser" time="24.945" classname="scripts.Demo">
    <failure type="java.lang.AssertionError" message="null">
      <![CDATA[java.lang.AssertionError: null
	at org.testng.Assert.fail(Assert.java:94)
	at org.testng.Assert.fail(Assert.java:101)
	at scripts.Demo.createUser(Demo.java:12)
	at sun.reflect.NativeMethodAccessorImpl.invoke0(Native Method)
	at sun.reflect.NativeMethodAccessorImpl.invoke(Unknown Source)
	at sun.reflect.DelegatingMethodAccessorImpl.invoke(Unknown Source)
	at java.lang.reflect.Method.invoke(Unknown Source)
	at org.testng.internal.MethodInvocationHelper.invokeMethod(MethodInvocationHelper.java:86)
	at org.testng.internal.Invoker.invokeMethod(Invoker.java:645)
	at org.testng.internal.Invoker.invokeTestMethod(Invoker.java:822)
	at org.testng.internal.Invoker.invokeTestMethods(Invoker.java:1130)
	at org.testng.internal.TestMethodWorker.invokeTestMethods(TestMethodWorker.java:129)
	at org.testng.internal.TestMethodWorker.run(TestMethodWorker.java:112)
	at org.testng.TestRunner.privateRun(TestRunner.java:782)
	at org.testng.TestRunner.run(TestRunner.java:632)
	at org.testng.SuiteRunner.runTest(SuiteRunner.java:366)
	at org.testng.SuiteRunner.runSequentially(SuiteRunner.java:361)
	at org.testng.SuiteRunner.privateRun(SuiteRunner.java:319)
	at org.testng.SuiteRunner.run(SuiteRunner.java:268)
	at org.testng.SuiteRunnerWorker.runSuite(SuiteRunnerWorker.java:52)
	at org.testng.SuiteRunnerWorker.run(SuiteRunnerWorker.java:86)
	at org.testng.TestNG.runSuitesSequentially(TestNG.java:1244)
	at org.testng.TestNG.runSuitesLocally(TestNG.java:1169)
	at org.testng.TestNG.run(TestNG.java:1064)
	at org.testng.remote.RemoteTestNG.run(RemoteTestNG.java:113)
	at org.testng.remote.RemoteTestNG.initAndRun(RemoteTestNG.java:206)
	at org.testng.remote.RemoteTestNG.main(RemoteTestNG.java:177)
]]>
    </failure>
  </testcase> <!-- createUser -->
  <testcase name="deleteUser" time="0.000" classname="scripts.Demo">
    <error type="java.lang.Throwable" message="Method Demo.deleteUser()[pri:0, instance:scripts.Demo@17246de] depends on not successfully finished methods">
      <![CDATA[java.lang.Throwable: Method Demo.deleteUser()[pri:0, instance:scripts.Demo@17246de] depends on not successfully finished methods
	at org.testng.internal.Invoker.invokeTestMethods(Invoker.java:1039)
	at org.testng.internal.TestMethodWorker.invokeTestMethods(TestMethodWorker.java:129)
	at org.testng.internal.TestMethodWorker.run(TestMethodWorker.java:112)
	at org.testng.TestRunner.privateRun(TestRunner.java:782)
	at org.testng.TestRunner.run(TestRunner.java:632)
	at org.testng.SuiteRunner.runTest(SuiteRunner.java:366)
	at org.testng.SuiteRunner.runSequentially(SuiteRunner.java:361)
	at org.testng.SuiteRunner.privateRun(SuiteRunner.java:319)
	at org.testng.SuiteRunner.run(SuiteRunner.java:268)
	at org.testng.SuiteRunnerWorker.runSuite(SuiteRunnerWorker.java:52)
	at org.testng.SuiteRunnerWorker.run(SuiteRunnerWorker.java:86)
	at org.testng.TestNG.runSuitesSequentially(TestNG.java:1244)
	at org.testng.TestNG.runSuitesLocally(TestNG.java:1169)
	at org.testng.TestNG.run(TestNG.java:1064)
	at org.testng.remote.RemoteTestNG.run(RemoteTestNG.java:113)
	at org.testng.remote.RemoteTestNG.initAndRun(RemoteTestNG.java:206)
	at org.testng.remote.RemoteTestNG.main(RemoteTestNG.java:177)
]]>
    </error>
  </testcase> <!-- deleteUser -->
</testsuite> <!-- scripts.Demo -->
